INFO 2019-03-14 19:38:44,635 basehttp 124 "GET /v0.10/overdue_worker/ HTTP/1.1" 200 5760
WARNING 2019-03-19 10:20:19,897 base 152 Not Found: /v9/
WARNING 2019-03-19 10:20:28,934 base 152 Not Found: /favicon.ico
WARNING 2019-03-21 15:55:37,023 base 152 Not Found: /v0.10/media/data/2019/01/26/2019-01-26-10-44-38-988000/北京最新路网可用作路径分析GDB.rar
WARNING 2019-03-21 17:34:48,631 base 152 Not Found: /favicon.ico
ERROR 2019-03-22 15:32:13,549 exception 135 Internal Server Error: /v0.10/user/login
Traceback (most recent call last):
  File "C:\Python27\ArcGIS10.2\lib\site-packages\django\core\handlers\exception.py", line 41, in inner
    response = get_response(request)
  File "C:\Python27\ArcGIS10.2\lib\site-packages\django\utils\deprecation.py", line 138, in __call__
    response = self.process_request(request)
  File "C:\Python27\ArcGIS10.2\lib\site-packages\django\middleware\common.py", line 64, in process_request
    path = self.get_full_path_with_slash(request)
  File "C:\Python27\ArcGIS10.2\lib\site-packages\django\middleware\common.py", line 104, in get_full_path_with_slash
    'url': request.get_host() + new_path,
RuntimeError: You called this URL via POST, but the URL doesn't end in a slash and you have APPEND_SLASH set. Django can't redirect to the slash URL while maintaining POST data. Change your form to point to 192.168.3.120:8000/v0.10/user/login/ (note the trailing slash), or set APPEND_SLASH=False in your Django settings.
ERROR 2019-03-22 15:48:54,043 exception 135 Internal Server Error: /v0.10/user/login
Traceback (most recent call last):
  File "C:\Python27\ArcGIS10.2\lib\site-packages\django\core\handlers\exception.py", line 41, in inner
    response = get_response(request)
  File "C:\Python27\ArcGIS10.2\lib\site-packages\django\utils\deprecation.py", line 138, in __call__
    response = self.process_request(request)
  File "C:\Python27\ArcGIS10.2\lib\site-packages\django\middleware\common.py", line 64, in process_request
    path = self.get_full_path_with_slash(request)
  File "C:\Python27\ArcGIS10.2\lib\site-packages\django\middleware\common.py", line 104, in get_full_path_with_slash
    'url': request.get_host() + new_path,
RuntimeError: You called this URL via POST, but the URL doesn't end in a slash and you have APPEND_SLASH set. Django can't redirect to the slash URL while maintaining POST data. Change your form to point to 192.168.3.120:8000/v0.10/user/login/ (note the trailing slash), or set APPEND_SLASH=False in your Django settings.
WARNING 2019-03-22 15:49:17,424 base 152 Not Found: /favicon.ico
ERROR 2019-03-22 15:49:23,604 exception 135 Internal Server Error: /v0.10/user/login
Traceback (most recent call last):
  File "C:\Python27\ArcGIS10.2\lib\site-packages\django\core\handlers\exception.py", line 41, in inner
    response = get_response(request)
  File "C:\Python27\ArcGIS10.2\lib\site-packages\django\utils\deprecation.py", line 138, in __call__
    response = self.process_request(request)
  File "C:\Python27\ArcGIS10.2\lib\site-packages\django\middleware\common.py", line 64, in process_request
    path = self.get_full_path_with_slash(request)
  File "C:\Python27\ArcGIS10.2\lib\site-packages\django\middleware\common.py", line 104, in get_full_path_with_slash
    'url': request.get_host() + new_path,
RuntimeError: You called this URL via POST, but the URL doesn't end in a slash and you have APPEND_SLASH set. Django can't redirect to the slash URL while maintaining POST data. Change your form to point to 192.168.3.120:8000/v0.10/user/login/ (note the trailing slash), or set APPEND_SLASH=False in your Django settings.
WARNING 2019-03-22 16:25:09,855 base 152 Not Found: /v0.10/table/list
WARNING 2019-03-22 16:27:02,661 base 152 Not Found: /v0.10/table/list
WARNING 2019-03-22 16:27:53,936 base 152 Not Found: /v0.10/table/list
WARNING 2019-03-25 20:54:08,200 base 152 Not Found: /v0.10/resultfile/
WARNING 2019-03-25 21:20:01,473 base 152 Not Found: /v0.10/fileinfos/
WARNING 2019-03-25 21:20:03,667 base 152 Not Found: /v0.10/fileinfos/
WARNING 2019-03-25 21:20:05,914 base 152 Not Found: /v0.10/fileinfos/
WARNING 2019-03-26 08:31:03,529 base 152 Not Found: /v0.10/fileinfos/
WARNING 2019-03-26 08:31:05,818 base 152 Not Found: /v0.10/fileinfos/
WARNING 2019-03-26 08:31:54,000 base 152 Not Found: /v0.10/fileinfos/
WARNING 2019-03-26 08:38:43,802 base 152 Not Found: /v0.10/resultfile/
WARNING 2019-03-26 08:39:43,487 base 152 Not Found: /v0.10/resultfile/
WARNING 2019-03-26 08:43:19,711 base 152 Not Found: /v0.10/resultfile/
WARNING 2019-03-26 08:43:47,086 base 152 Not Found: /v0.10/resultfile/
WARNING 2019-03-26 08:50:39,226 base 152 Not Found: /v0.10/resultfile/
WARNING 2019-03-29 10:46:03,085 base 152 Not Found: /v0.10/handoutlistnames/
WARNING 2019-03-29 10:46:50,280 base 152 Not Found: /v0.10/handoutlistnames/
WARNING 2019-03-29 10:46:56,901 base 152 Not Found: /v0.10/handoutlistnames/
WARNING 2019-03-29 10:47:11,193 base 152 Not Found: /v0.10/handoutlistnames/
WARNING 2019-03-29 10:47:11,321 base 152 Not Found: /favicon.ico
ERROR 2019-04-01 10:11:56,762 exception 135 Internal Server Error: /v0.10/taskpackages/
Traceback (most recent call last):
  File "C:\Python27\ArcGIS10.2\lib\site-packages\django\core\handlers\exception.py", line 41, in inner
    response = get_response(request)
  File "C:\Python27\ArcGIS10.2\lib\site-packages\django\core\handlers\base.py", line 187, in _get_response
    response = self.process_exception_by_middleware(e, request)
  File "C:\Python27\ArcGIS10.2\lib\site-packages\django\core\handlers\base.py", line 185, in _get_response
    response = wrapped_callback(request, *callback_args, **callback_kwargs)
  File "C:\Python27\ArcGIS10.2\lib\site-packages\django\views\decorators\csrf.py", line 58, in wrapped_view
    return view_func(*args, **kwargs)
  File "C:\Python27\ArcGIS10.2\lib\site-packages\rest_framework\viewsets.py", line 116, in view
    return self.dispatch(request, *args, **kwargs)
  File "C:\Python27\ArcGIS10.2\lib\site-packages\rest_framework\views.py", line 495, in dispatch
    response = self.handle_exception(exc)
  File "C:\Python27\ArcGIS10.2\lib\site-packages\rest_framework\views.py", line 455, in handle_exception
    self.raise_uncaught_exception(exc)
  File "C:\Python27\ArcGIS10.2\lib\site-packages\rest_framework\views.py", line 492, in dispatch
    response = handler(request, *args, **kwargs)
  File "C:\Python27\ArcGIS10.2\lib\site-packages\rest_framework\mixins.py", line 40, in list
    queryset = self.filter_queryset(self.get_queryset())
  File "C:\Users\Administrator\Desktop\RGSManager\taskpackages\views.py", line 89, in get_queryset
    if taskpackage_owner.endtime is not None and taskpackage_son.updatetime is not None:
AttributeError: 'NoneType' object has no attribute 'updatetime'
ERROR 2019-04-01 10:11:57,187 basehttp 124 "GET /v0.10/taskpackages/?regiontask_name=%E4%B8%9C%E5%8D%97%E5%8C%BA%E5%9F%9F HTTP/1.1" 500 101095
ERROR 2019-04-01 10:12:32,658 exception 135 Internal Server Error: /v0.10/taskpackages/
Traceback (most recent call last):
  File "C:\Python27\ArcGIS10.2\lib\site-packages\django\core\handlers\exception.py", line 41, in inner
    response = get_response(request)
  File "C:\Python27\ArcGIS10.2\lib\site-packages\django\core\handlers\base.py", line 187, in _get_response
    response = self.process_exception_by_middleware(e, request)
  File "C:\Python27\ArcGIS10.2\lib\site-packages\django\core\handlers\base.py", line 185, in _get_response
    response = wrapped_callback(request, *callback_args, **callback_kwargs)
  File "C:\Python27\ArcGIS10.2\lib\site-packages\django\views\decorators\csrf.py", line 58, in wrapped_view
    return view_func(*args, **kwargs)
  File "C:\Python27\ArcGIS10.2\lib\site-packages\rest_framework\viewsets.py", line 116, in view
    return self.dispatch(request, *args, **kwargs)
  File "C:\Python27\ArcGIS10.2\lib\site-packages\rest_framework\views.py", line 495, in dispatch
    response = self.handle_exception(exc)
  File "C:\Python27\ArcGIS10.2\lib\site-packages\rest_framework\views.py", line 455, in handle_exception
    self.raise_uncaught_exception(exc)
  File "C:\Python27\ArcGIS10.2\lib\site-packages\rest_framework\views.py", line 492, in dispatch
    response = handler(request, *args, **kwargs)
  File "C:\Python27\ArcGIS10.2\lib\site-packages\rest_framework\mixins.py", line 40, in list
    queryset = self.filter_queryset(self.get_queryset())
  File "C:\Users\Administrator\Desktop\RGSManager\taskpackages\views.py", line 89, in get_queryset
    if taskpackage_owner.endtime is not None and taskpackage_son.updatetime is not None:
AttributeError: 'NoneType' object has no attribute 'updatetime'
ERROR 2019-04-01 10:12:33,059 basehttp 124 "GET /v0.10/taskpackages/?regiontask_name=%E4%B8%9C%E5%8D%97%E5%8C%BA%E5%9F%9F HTTP/1.1" 500 101095
INFO 2019-04-01 10:15:07,845 basehttp 124 "GET /v0.10/taskpackages/?regiontask_name=%E4%B8%9C%E5%8D%97%E5%8C%BA%E5%9F%9F HTTP/1.1" 200 19666
INFO 2019-04-01 10:16:00,897 basehttp 124 "GET /v0.10/taskpackages/?regiontask_name=%E4%B8%9C%E5%8D%97%E5%8C%BA%E5%9F%9F HTTP/1.1" 200 16806
INFO 2019-04-01 10:20:01,792 basehttp 124 "POST /v0.10/taskpackages/?regiontask_name=%E4%B8%9C%E5%8D%97%E5%8C%BA%E5%9F%9F HTTP/1.1" 201 13928
INFO 2019-04-01 10:20:36,267 basehttp 124 "GET /v0.10/taskpackages/ HTTP/1.1" 200 15743
INFO 2019-04-01 10:22:49,707 basehttp 124 "GET /v0.10/taskpackages/?regiontask_name=%E4%B8%9C%E5%8D%97%E5%8C%BA%E5%9F%9F HTTP/1.1" 200 17699
INFO 2019-04-01 10:26:12,391 basehttp 124 "GET /v0.10/taskpackages/?regiontask_name=%E4%B8%9C%E5%8D%97%E5%8C%BA%E5%9F%9F HTTP/1.1" 200 17699
INFO 2019-04-01 10:26:32,628 basehttp 124 "GET /v0.10/ HTTP/1.1" 200 7112
INFO 2019-04-01 10:26:35,382 basehttp 124 "GET /v0.10/taskpackagesons/ HTTP/1.1" 200 10903
INFO 2019-04-01 10:26:54,433 basehttp 124 "POST /v0.10/taskpackagesons/ HTTP/1.1" 201 11702
INFO 2019-04-01 10:26:57,249 basehttp 124 "GET /v0.10/ HTTP/1.1" 200 7112
INFO 2019-04-01 10:26:59,410 basehttp 124 "GET /v0.10/taskpackages/ HTTP/1.1" 200 15743
INFO 2019-04-01 10:36:16,486 basehttp 124 "GET /v0.10/ HTTP/1.1" 200 7112
INFO 2019-04-01 10:36:18,737 basehttp 124 "GET /v0.10/taskpackages/ HTTP/1.1" 200 15743
INFO 2019-04-01 10:36:35,191 basehttp 124 "GET /v0.10/taskpackages/?regiontask_name=%E4%B8%9C%E5%8D%97%E5%8C%BA%E5%9F%9F HTTP/1.1" 200 17700
INFO 2019-04-01 10:36:36,355 basehttp 124 "GET /v0.10/taskpackages/?regiontask_name=%E4%B8%9C%E5%8D%97%E5%8C%BA%E5%9F%9F HTTP/1.1" 200 17700
ERROR 2019-04-01 10:36:36,361 basehttp 124 "GET /v0.10/taskpackages/?regiontask_name=%E4%B8%9C%E5%8D%97%E5%8C%BA%E5%9F%9F HTTP/1.1" 500 59
INFO 2019-04-01 10:37:56,618 basehttp 124 "POST /v0.10/taskpackages/?regiontask_name=%E4%B8%9C%E5%8D%97%E5%8C%BA%E5%9F%9F HTTP/1.1" 201 13928
INFO 2019-04-01 10:37:59,470 basehttp 124 "GET /v0.10/ HTTP/1.1" 200 7112
INFO 2019-04-01 10:38:04,977 basehttp 124 "GET /v0.10/taskpackagesons/ HTTP/1.1" 200 10903
INFO 2019-04-01 10:38:20,598 basehttp 124 "POST /v0.10/taskpackagesons/ HTTP/1.1" 201 11702
INFO 2019-04-01 10:38:23,940 basehttp 124 "GET /v0.10/ HTTP/1.1" 200 7112
INFO 2019-04-01 10:41:33,417 basehttp 124 "GET /v0.10/taskpackages/ HTTP/1.1" 200 15743
INFO 2019-04-01 10:43:15,394 basehttp 124 "GET /v0.10/taskpackages/?regiontask_name=%E4%B8%9C%E5%8D%97%E5%8C%BA%E5%9F%9F HTTP/1.1" 200 18589
ERROR 2019-04-01 10:43:15,395 basehttp 124 "GET /v0.10/taskpackages/?regiontask_name=%E4%B8%9C%E5%8D%97%E5%8C%BA%E5%9F%9F HTTP/1.1" 500 59
INFO 2019-04-01 10:43:27,948 basehttp 124 "GET /v0.10/taskpackages/?regiontask_name=%E4%B8%9C%E5%8D%97%E5%8C%BA%E5%9F%9F HTTP/1.1" 200 18589
